ERROR:cdsapi:Message: no data is available within your requested subset
ERROR:cdsapi:Reason:  Request returned no data
ERROR:cdsapi:  Traceback (most recent call last):
ERROR:cdsapi:    File "/opt/cdstoolbox/cdscompute/cdscompute/cdshandlers/services/handler.py", line 49, in handle_request
ERROR:cdsapi:      result = cached(context.method, proc, context, context.args, context.kwargs)
ERROR:cdsapi:    File "/opt/cdstoolbox/cdscompute/cdscompute/caching.py", line 108, in cached
ERROR:cdsapi:      result = proc(context, *context.args, **context.kwargs)
ERROR:cdsapi:    File "/opt/cdstoolbox/cdscompute/cdscompute/services.py", line 118, in __call__
ERROR:cdsapi:      return p(*args, **kwargs)
ERROR:cdsapi:    File "/opt/cdstoolbox/cdscompute/cdscompute/services.py", line 59, in __call__
ERROR:cdsapi:      return self.proc(context, *args, **kwargs)
ERROR:cdsapi:    File "/home/cds/cdsservices/services/mars.py", line 347, in internal
ERROR:cdsapi:      return mars(context, request, **kwargs)
ERROR:cdsapi:    File "/home/cds/cdsservices/services/mars.py", line 48, in mars
ERROR:cdsapi:      execute_mars(context, requests)
ERROR:cdsapi:    File "/home/cds/cdsservices/services/mars.py", line 196, in execute_mars
ERROR:cdsapi:      raise NoDataException("Request returned no data", '')
ERROR:cdsapi:  cdsinf.exceptions.NoDataException: Request returned no data
ERROR:root:msmtsno data is available within your requested subset. Request returned no data.
Traceback (most recent call last):
  File "/Users/spindicate/Documents/programming/zooscraper/casestudy/update/helpers.py", line 162, in log_exception
    result = func(*args, **kwargs)
  File "/Users/spindicate/Documents/programming/zooscraper/casestudy/update/funcs.py", line 519, in msmts
    MSMT_PATH + temp_file
  File "/Users/spindicate/Documents/programming/envs/zooenv/lib/python3.7/site-packages/cdsapi/api.py", line 317, in retrieve
    result = self._api('%s/resources/%s' % (self.url, name), request, 'POST')
  File "/Users/spindicate/Documents/programming/envs/zooenv/lib/python3.7/site-packages/cdsapi/api.py", line 458, in _api
    raise Exception("%s. %s." % (reply['error'].get('message'), reply['error'].get('reason')))
Exception: no data is available within your requested subset. Request returned no data.
